Workbook

Sheet EVIDENCE_TABLE
A1: Requirement | B1: Tier | C1: MoSCoW | D1: Weight | E1: Kano | F1: Destination | G1: Score | H1: Data_Point_Description | I1: Value | J1: Unit | K1: Provider_or_Context | L1: Year | M1: Confidence | N1: Source | O1: Source_URL | P1: Score_Justification
A2: Gravity >0.67g | B2: 1 | C2: Must | D2: 10 | E2: Basic | F2: Moon | G2: 2 | H2: Native surface gravity | I2: 0.166 | J2: g | K2: Measured | L2: 2025 | M2: Actual | N2: NTRS Gravity 2021 | O2: https://ntrs.nasa.gov/api/citations/20210019591/downloads/ICES-2021-142.pdf | P2: 0.166g far below 0.67g health threshold. Score 2: fails basic requirement, partial mitigation via centrifuge theoretically possible but unproven at scale.
A3: Gravity >0.67g | B3: 1 | C3: Must | D3: 10 | E3: Basic | F3: Mars | G3: 4 | H3: Native surface gravity | I3: 0.378 | J3: g | K3: Measured | L3: 2025 | M3: Actual | N3: NTRS Gravity 2021 | O3: https://ntrs.nasa.gov/api/citations/20210019591/downloads/ICES-2021-142.pdf | P3: 0.378g marginal, below 0.67g threshold. Score 4: closer to threshold, mouse studies suggest partial but not full mitigation of atrophy.
A4: Gravity >0.67g | B4: 1 | C4: Must | D4: 10 | E4: Basic | F4: Mars | G4: 4 | H4: Mouse skeletal muscle study at 0.33g | I4: 0.33 | J4: g | K4: URI/Harvard/JAXA ISS study | L4: 2026 | M4: Actual | N4: Universe Today / Kingston Today | O4: https://www.universetoday.com/articles/how-will-martian-gravity-affect-skeletal-muscle | P4: 24 mice at 4 gravity levels: 0.33g mitigated but did not prevent muscle atrophy.
A5: Gravity >0.67g | B5: 1 | C5: Must | D5: 10 | E5: Basic | F5: Orbital | G5: 9 | H5: O'Neill cylinder rotation | I5: 1 | J5: g | K5: Design parameter | L5: 2025 | M5: Projected | N5: NASA SP-413 | O5: https://settlement.arc.nasa.gov/75SummerStudy/Table_of_Contents1.html | P5: Full 1g achievable via rotation at 500m+ radius. Score 9: engineering solution proven in concept, tunable.
A6: Gravity >0.67g | B6: 1 | C6: Must | D6: 10 | E6: Basic | F6: Orbital | G6: 9 | H6: Stanford Torus rotation | I6: 1 | J6: g | K6: Design parameter | L6: 1975 | M6: Projected | N6: NASA SP-413 | O6: https://settlement.arc.nasa.gov/75SummerStudy/Table_of_Contents1.html | P6: 895m radius at 1 RPM provides 1g with minimal Coriolis effect.
A7: Gravity >0.67g | B7: 1 | C7: Must | D7: 10 | E7: Basic | F7: Orbital | G7: 9 | H7: Kalpana One rotation | I7: 1 | J7: g | K7: Al Globus design | L7: 2007 | M7: Projected | N7: Al Globus 2007 | O7: https://settlement.arc.nasa.gov/Kalpana/KalpanaTwo.html | P7: 250m radius at 1.9 RPM, optimized for lower mass.
A8: Radiation <600 mSv/career | B8: 1 | C8: Must | D8: 9 | E8: Basic | F8: Moon | G8: 6 | H8: Unshielded surface dose | I8: 380 | J8: mSv/yr | K8: No shielding | L8: 2025 | M8: Actual | N8: NASA-STD-3001 | O8: https://www.nasa.gov/wp-content/uploads/2023/11/nasa-std-3001-vol-1-rev-c-with-signature.pdf | P8: Unshielded: 1.6 years to career limit.
A9: Radiation <600 mSv/career | B9: 1 | C9: Must | D9: 9 | E9: Basic | F9: Moon | G9: 6 | H9: 2m regolith shielded dose | I9: 50 | J9: mSv/yr | K9: Regolith burial | L9: 2025 | M9: Estimated | N9: NASA-STD-3001 | O9: https://www.nasa.gov/wp-content/uploads/2023/11/nasa-std-3001-vol-1-rev-c-with-signature.pdf | P9: 12 years to career limit with regolith. Score 6: engineering solvable but requires construction.
A10: Radiation <600 mSv/career | B10: 1 | C10: Must | D10: 9 | E10: Basic | F10: Moon | G10: 6 | H10: Lava tube shielded dose | I10: 10 | J10: mSv/yr | K10: Natural basalt | L10: 2025 | M10: Estimated | N10: NASA-STD-3001 | O10: https://www.nasa.gov/wp-content/uploads/2023/11/nasa-std-3001-vol-1-rev-c-with-signature.pdf | P10: 60 years to limit. Best lunar option if accessible.
A11: Radiation <600 mSv/career | B11: 1 | C11: Must | D11: 9 | E11: Basic | F11: Mars | G11: 6 | H11: Unshielded surface dose (Curiosity RAD) | I11: 234 | J11: mSv/yr | K11: MSL/RAD instrument | L11: 2025 | M11: Actual | N11: Curiosity RAD | O11: https://mars.nasa.gov/msl/mission/instruments/rad/ | P11: Actual measurement on Mars surface. 2.6 years to career limit unshielded.
A12: Radiation <600 mSv/career | B12: 1 | C12: Must | D12: 9 | E12: Basic | F12: Mars | G12: 6 | H12: 1m regolith shielded dose | I12: 100 | J12: mSv/yr | K12: Regolith + atmosphere | L12: 2025 | M12: Estimated | N12: Curiosity RAD | O12: https://mars.nasa.gov/msl/mission/instruments/rad/ | P12: 6 years to limit. Atmosphere provides ~50% reduction baseline. Score 6: similar engineering challenge to Moon.
A13: Radiation <600 mSv/career | B13: 1 | C13: Must | D13: 9 | E13: Basic | F13: Mars | G13: 6 | H13: Lava tube shielded dose | I13: 15 | J13: mSv/yr | K13: Natural basalt | L13: 2025 | M13: Estimated | N13: Curiosity RAD | O13: https://mars.nasa.gov/msl/mission/instruments/rad/ | P13: 40 years to limit. Best Mars option.
... A35: Communications latency | B35: 2 | C35: Should | D35: 5 | E35: Performance | F35: Orbital | G35: 8 | H35: Signal delay one-way (LEO) | I35: 0.03 | J35: seconds | K35: TDRSS relay | L35: 2025 | M35: Actual | N35: General | O35: Various | P35: Score 8: effectively real-time. Full ground support available.
A36: Behavioral health / crew sustainability | B36: 2 | C36: Should | D36: 6 | E36: Performance | F36: Moon | G36: 7 | H36: Expert assessment: isolation and confinement | I36: — | J36: — | K36: Expert consensus | L36: 2025 | M36: Expert | N36: Red Risks Study | O36: https://www.nature.com/articles/s41526-020-00124-6 | P36: Score 7: 1.3s latency allows Earth contact. 2-week crew rotations feasible. Visual of Earth aids morale.
A37: Behavioral health / crew sustainability | B37: 2 | C37: Should | D37: 6 | E37: Performance | F37: Mars | G37: 3 | H37: Expert assessment: isolation and confinement | I37: — | J37: — | K37: Expert consensus | L37: 2025 | M37: Expert | N37: Red Risks Study | O37: https://www.nature.com/articles/s41526-020-00124-6 | P37: Score 3: 4-24 min latency, 26-month isolation, extreme psychological demands. No precedent for multi-year confinement at this distance.
A38: Behavioral health / crew sustainability | B38: 2 | C38: Should | D38: 6 | E38: Performance | F38: Orbital | G38: 6 | H38: Expert assessment: isolation and confinement | I38: — | J38: — | K38: Expert consensus | L38: 2025 | M38: Expert | N38: Red Risks Study | O38: https://www.nature.com/articles/s41526-020-00124-6 | P38: Score 6: zero latency and crew rotation possible but confined environment. ISS analog data available.
A39: ISRU potential | B39: 3 | C39: Should | D39: 7 | E39: Performance | F39: Moon | G39: 7 | H39: Ilmenite O2 extraction capacity | I39: 10 | J39: kg/day | K39: Regolith processing | L39: 2032 | M39: Projected | N39: LCROSS/NASA | O39: https://www.nasa.gov/mission_pages/LCROSS/main/index.html | P39: Oxygen from regolith, requires processing plant.
A40: ISRU potential | B40: 3 | C40: Should | D40: 7 | E40: Performance | F40: Moon | G40: 7 | H40: Polar ice mining capacity | I40: 50 | J40: kg/day | K40: Crater ice deposits | L40: 2032 | M40: Projected | N40: LCROSS/NASA | O40: https://www.nasa.gov/mission_pages/LCROSS/main/index.html | P40: LCROSS confirmed deposits. Score 7: 60 kg/day total, water + O2 achievable.
A41: ISRU potential | B41: 3 | C41: Should | D41: 7 | E41: Performance | F41: Mars | G41: 7 | H41: Scaled MOXIE O2 production | I41: 2 | J41: kg/day | K41: CO2 electrolysis | L41: 2035 | M41: Projected | N41: MOXIE Results | O41: https://www.nasa.gov/missions/mars-2020-perseverance/perseverance-rover/nasas-moxie-experiment/ | P41: Scaled from 12g/hr demo.
A42: ISRU potential | B42: 3 | C42: Should | D42: 7 | E42: Performance | F42: Mars | G42: 7 | H42: Subsurface ice extraction | I42: 20 | J42: kg/day | K42: SHARAD/MARSIS data | L42: 2035 | M42: Projected | N42: NASA/JPL | O42: https://mars.nasa.gov/ | P42: SHARAD confirmed extensive ice sheets.
A43: ISRU potential | B43: 3 | C43: Should | D43: 7 | E43: Performance | F43: Mars | G43: 7 | H43: Sabatier methane production | I43: 5 | J43: kg/day | K43: CO2 + H2 | L43: 2030 | M43: Projected | N43: MOXIE Results | O43: https://www.nasa.gov/missions/mars-2020-perseverance/perseverance-rover/nasas-moxie-experiment/ | P43: Score 7: 27 kg/day total, diverse resources. Well-understood chemistry.
A44: ISRU potential | B44: 3 | C44: Should | D44: 7 | E44: Performance | F44: Orbital | G44: 3 | H44: No natural ISRU resources | I44: 0 | J44: kg/day | K44: No resources in orbit | L44: 2025 | M44: Actual | N44: General | O44: Various | P44: Score 3: zero ISRU. Fully dependent on Earth resupply or imported material.
A45: Energy independence | B45: 3 | C45: Should | D45: 7 | E45: Performance | F45: Moon | G45: 4 | H45: Kilopower 10kW specific power | I45: 6.7 | J45: W/kg | K45: NASA/LANL fission | L45: 2025 | M45: Projected | N45: Kilopower KRUSTY | O45: https://www.nasa.gov/directorates/stmd/tech-demo-missions-program/kilopower/ | P45: Score 4: nuclear required due to 14-day night. Lower specific power than solar alternatives.
A46: Energy independence | B46: 3 | C46: Should | D46: 7 | E46: Performance | F46: Moon | G46: 4 | H46: Rolls-Royce micro reactor | I46: 10 | J46: W/kg | K46: UK Space Agency | L46: 2030 | M46: Projected | N46: General | O46: Various | P46: Alternative fission option, higher specific power but lower TRL.
A47: Energy independence | B47: 3 | C47: Should | D47: 7 | E47: Performance | F47: Mars | G47: 5 | H47: Mars solar panel specific power | I47: 50 | J47: W/kg | K47: 43% Earth irradiance | L47: 2025 | M47: Actual | N47: Curiosity RAD/General | O47: https://mars.nasa.gov/ | P47: Higher specific power but dust storms cause blackouts. Score 5: solar + nuclear hybrid needed.
A48: Energy independence | B48: 3 | C48: Should | D48: 7 | E48: Performance | F48: Mars | G48: 5 | H48: Kilopower on Mars | I48: 6.7 | J48: W/kg | K48: NASA/LANL fission | L48: 2025 | M48: Projected | N48: Kilopower KRUSTY | O48: https://www.nasa.gov/directorates/stmd/tech-demo-missions-program/kilopower/ | P48: Backup for dust storm blackouts.
A49: Energy independence | B49: 3 | C49: Should | D49: 7 | E49: Performance | F49: Orbital | G49: 8 | H49: ISS iROSA arrays | I49: 8.6 | J49: W/kg | K49: ISS proven | L49: 2024 | M49: Actual | N49: NASA OIG | O49: https://oig.nasa.gov/ | P49: Proven tech, continuous sunlight in proper orbit.
A50: Energy independence | B50: 3 | C50: Should | D50: 7 | E50: Performance | F50: Orbital | G50: 8 | H50: Large orbital solar array | I50: 100 | J50: W/kg | K50: Future design | L50: 2030 | M50: Projected | N50: General | O50: Various | P50: Score 8: continuous solar, no dust, no night cycle. Highest potential specific power.
... A69: Cost of failure / recovery | B69: 3 | C69: Must | D69: 7 | E69: Basic | F69: Orbital | G69: 5 | H69: LEO station total loss | I69: 5000000000 | J69: USD | K69: Structural failure | L69: 2025 | M69: Estimated | N69: NASA OIG | O69: https://oig.nasa.gov/ | P69: Worst case for orbital.
A70: Maintenance crew time ratio | B70: 3 | C70: Should | D70: 6 | E70: Performance | F70: Moon | G70: 5 | H70: Expert assessment | I70: — | J70: — | K70: Expert consensus | L70: 2025 | M70: Expert | N70: NASA BVAD | O70: https://ntrs.nasa.gov/api/citations/20210024855/downloads/BVAD_2.15.22-final.pdf | P70: Score 5: lunar dust abrasion increases maintenance. Limited spares but resupply feasible.
A71: Maintenance crew time ratio | B71: 3 | C71: Should | D71: 6 | E71: Performance | F71: Mars | G71: 4 | H71: Expert assessment | I71: — | J71: — | K71: Expert consensus | L71: 2025 | M71: Expert | N71: NASA BVAD | O71: https://ntrs.nasa.gov/api/citations/20210024855/downloads/BVAD_2.15.22-final.pdf | P71: Score 4: all spares pre-positioned or ISRU-manufactured. Extreme supply chain.
A72: Maintenance crew time ratio | B72: 3 | C72: Should | D72: 6 | E72: Performance | F72: Orbital | G72: 5 | H72: Expert assessment | I72: — | J72: — | K72: Expert consensus | L72: 2025 | M72: Expert | N72: NASA BVAD | O72: https://ntrs.nasa.gov/api/citations/20210024855/downloads/BVAD_2.15.22-final.pdf | P72: Score 5: LEO resupply feasible, modular design, ISS heritage data.
A73: Automation / remote ops capability | B73: 3 | C73: Should | D73: 6 | E73: Performance | F73: Moon | G73: 7 | H73: Expert assessment | I73: — | J73: — | K73: Expert consensus | L73: 2025 | M73: Expert | N73: General | O73: Various | P73: Score 7: low latency enables teleoperation from Earth.
A74: Automation / remote ops capability | B74: 3 | C74: Should | D74: 6 | E74: Performance | F74: Mars | G74: 3 | H74: Expert assessment | I74: — | J74: — | K74: Expert consensus | L74: 2025 | M74: Expert | N74: General | O74: Various | P74: Score 3: high latency forces full autonomy. AI-driven operations required.
A75: Automation / remote ops capability | B75: 3 | C75: Should | D75: 6 | E75: Performance | F75: Orbital | G75: 7 | H75: Expert assessment | I75: — | J75: — | K75: Expert consensus | L75: 2025 | M75: Expert | N75: General | O75: Various | P75: Score 7: zero latency enables full remote ops. Proven ISS model.
A76: Monitoring / incident response | B76: 3 | C76: Should | D76: 5 | E76: Performance | F76: Moon | G76: 8 | H76: Expert assessment | I76: — | J76: — | K76: Expert consensus | L76: 2025 | M76: Expert | N76: General | O76: Various | P76: Score 8: near real-time monitoring, rapid Earth-based decision support.
A77: Monitoring / incident response | B77: 3 | C77: Should | D77: 5 | E77: Performance | F77: Mars | G77: 2 | H77: Expert assessment | I77: — | J77: — | K77: Expert consensus | L77: 2025 | M77: Expert | N77: General | O77: Various | P77: Score 2: delayed monitoring, crew must self-respond, no rapid evacuation.
A78: Monitoring / incident response | B78: 3 | C78: Should | D78: 5 | E78: Performance | F78: Orbital | G78: 7 | H78: Expert assessment | I78: — | J78: — | K78: Expert consensus | L78: 2025 | M78: Expert | N78: General | O78: Various | P78: Score 7: real-time monitoring, rapid evacuation possible.
A79: Resource consumption vs renewal rate | B79: 3 | C79: Should | D79: 6 | E79: Performance | F79: Moon | G79: 5 | H79: Expert assessment | I79: — | J79: — | K79: Expert consensus | L79: 2025 | M79: Expert | N79: LCROSS/MOXIE | O79: Various | P79: Score 5: some ISRU for water and O2, limited biological renewal.
...

Sheet README
A1: SPACE COLONY ARCHITECTURE — DATA ANALYSIS WORKBOOK
A2: Version 1.0 | April 2026
A4: PURPOSE
A5: This workbook separates raw sourced data from scoring. Scores are formula-derived, not hardcoded.
A6: Adding a data row to any RAW_* sheet auto-updates normalization and the final scoring matrix.
A8: SHEET STRUCTURE
A9: Sheet | B9: Purpose | C9: Who Edits
A10: README | B10: This page | C10: —
A11: DATA_DICTIONARY | B11: Column definitions, units, acceptable values for every raw data sheet | C11: Analyst
A12: GEMINI_PROMPTS | B12: Copy-paste prompts for Gemini to research and return structured data | C12: Analyst / AI
A13: SOURCE_REGISTRY | B13: Master list of all sources with IDs, URLs, access dates, reliability ratings | C13: Analyst
A14: RAW_Transport_Cost | B14: $/kg to destination by provider, year, vehicle | C14: Analyst / AI
A15: RAW_Operating_Cost | B15: Annual operating cost per capita by mission/habitat | C15: Analyst / AI
A16: RAW_ECLSS | B16: Life support mass, recovery rates, power, crew capacity | C16: Analyst / AI
A17: RAW_Radiation | B17: Dose rates by destination, shielding effectiveness | C17: Analyst / AI
A18: RAW_Gravity | B18: Surface gravity, health impact data, centrifuge specs | C18: Analyst / AI
A19: RAW_Comms_Latency | B19: Signal delay by destination, bandwidth | C19: Analyst / AI
A20: RAW_ISRU | B20: Resource availability, extraction rates, TRL | C20: Analyst / AI
... A26: QUAL_JUSTIFICATIONS | B26: Expert-rated qualitative metrics with justification text and citations | C26: Analyst
A28: COLOR CODING
A29: Blue text = hardcoded input (add/edit these)
A30: Black text = formula (do not manually edit)
A31: Green text = cross-sheet reference
A32: Yellow background = input cell
A33: Green background = formula cell
A35: INSTRUCTIONS FOR GEMINI / AI EXPANSION
A36: 1. Copy the prompt from GEMINI_PROMPTS for the metric you want to expand
A37: 2. Paste into Gemini with 'Return results as a CSV table matching these exact columns'
A38: 3. Paste Gemini's output into the corresponding RAW_* sheet as new rows
A39: 4. Add the source to SOURCE_REGISTRY with a new SRC_ID
A40: 5. Update the row count in NORM_ENGINE if the range needs extending
A41: 6. All scores auto-recalculate

Sheet DATA_DICTIONARY
A1: Sheet | B1: Column | C1: Data_Type | D1: Unit | E1: Required | F1: Valid_Range | G1: Description
A2: RAW_Transport_Cost | B2: Provider | C2: text | D2: — | E2: Y | F2: — | G2: Organization name (NASA, SpaceX, ESA, JAXA, etc.)
A3: RAW_Transport_Cost | B3: Vehicle | C3: text | D3: — | E3: Y | F3: — | G3: Launch vehicle or transport system name
A4: RAW_Transport_Cost | B4: Destination | C4: enum | D4: — | E4: Y | F4: LEO|Lunar_Surface|Lunar_Orbit|Mars_Surface|Mars_Orbit|L1|L2 | G4: Target destination
A5: RAW_Transport_Cost | B5: Year | C5: integer | D5: — | E5: Y | F5: 2000-2060 | G5: Year of estimate or projection
A6: RAW_Transport_Cost | B6: Cost_Per_Kg_USD | C6: number | D6: USD/kg | E6: Y | F6: >0 | G6: Cost to deliver 1 kg to destination in 2025 USD
A7: RAW_Transport_Cost | B7: Payload_Capacity_Kg | C7: number | D7: kg | E7: N | F7: >0 | G7: Max payload mass to destination
A8: RAW_Transport_Cost | B8: Reusability | C8: enum | D8: — | E8: N | F8: Expendable|Partial|Full | G8: Reuse capability
A9: RAW_Transport_Cost | B9: Confidence | C9: enum | D9: — | E9: Y | F9: Actual|Contracted|Projected|Estimated | G9: Data reliability level
A10: RAW_Transport_Cost | B10: SRC_ID | C10: text | D10: — | E10: Y | F10: SRC_### | G10: Reference to SOURCE_REGISTRY
A11: RAW_Transport_Cost | B11: Notes | C11: text | D11: — | E11: N | F11: — | G11: Any caveats or context
A12: RAW_Operating_Cost | B12: Mission_or_Habitat | C12: text | D12: — | E12: Y | F12: — | G12: Name (ISS, Gateway, Tiangong, etc.)
... A40: RAW_Radiation | B40: SRC_ID | C40: text | D40: — | E40: Y | F40: SRC_### | G40: Source reference

Sheet GEMINI_PROMPTS
A1: Metric | B1: Prompt_for_Gemini | C1: Target_Sheet | D1: Expected_Columns
A2: Transport Cost per Kg | B2: Research the cost per kilogram to deliver payload to the following destinations: LEO, Lunar Surface, Lunar Orbit, Mars Surface, Mars Orbit, Earth-Moon L1, Earth-Moon L2. Include data from NASA (SLS, Commercial Crew), SpaceX (Falcon 9, Falcon Heavy, Starship), ESA (Ariane 6), JAXA (H3), Roscosmos (Proton, Soyuz), ULA (Vulcan Centaur), Blue Origin (New Glenn), Rocket Lab (Neutron), China (Long March 5, Long March 9). For each, provide: Provider, Vehicle, Destination, Year of estimate, Cost_Per_Kg_USD (in 2025 dollars), Payload_Capacity_Kg, Reusability (Expendable/Partial/Full), Confidence (Actual/Contracted/Projected/Estimated), and the specific source URL. Return as a CSV table with those exact column headers. | C2: RAW_Transport_Cost | D2: Provider, Vehicle, Destination, Year, Cost_Per_Kg_USD, Payload_Capacity_Kg, Reusability, Confidence, SRC_ID, Notes
A3: Operating Cost per Capita | B3: Research annual operating costs for space habitats and missions. Include: ISS (NASA annual cost / crew), Tiangong (CNSA estimates), Lunar Gateway (projected), Artemis surface missions (projected per-crew costs), Mars Design Reference Mission 5.0 (NASA estimates), Orbital Reef (Blue Origin/Sierra Space projections), Starlab (Voyager/Airbus projections), Axiom Station, Vast Haven-1. For each provide: Mission_or_Habitat, Agency_or_Provider, Destination, Year, Annual_Cost_USD (in 2025 dollars), Crew_Size, Cost_Per_Capita_USD, Includes_Transport (TRUE/FALSE), Confidence (Actual/Contracted/Projected/Estimated), source URL. Return as CSV. | C3: RAW_Operating_Cost | D3: Mission_or_Habitat, Agency_or_Provider, Destination, Year, Annual_Cost_USD, Crew_Size, Cost_Per_Capita_USD, Includes_Transport, Confidence, SRC_ID, Notes
A4: ECLSS Specifications | B4: Research Environmental Control and Life Support System specifications. Include: ISS ECLSS (current), ISS ECLSS (upgraded Exploration ECLSS), Gateway ECLSS, Artemis Surface Habitat ECLSS, Mars Transit ECLSS (NASA DRM 5.0), Bigelow/Vast inflatable habitat ECLSS, ESA MELiSSA, JAXA ECLSS research, any Chinese Tiangong ECLSS data. For each provide: System_Name, Provider, Configuration (Open/Partially_Closed/Closed), Initial_Mass_Kg, Water_Recovery_Pct, O2_Recovery_Pct, Power_Requirement_kW, Crew_Capacity, TRL, source URL. Return as CSV. | C4: RAW_ECLSS | D4: System_Name, Provider, Configuration, Initial_Mass_Kg, Water_Recovery_Pct, O2_Recovery_Pct, Power_Requirement_kW, Crew_Capacity, Mass_Per_Crew_Kg, TRL, SRC_ID, Notes
A5: Radiation Exposure | B5: Research radiation dose rates at: LEO (inside ISS), Lunar surface (unshielded and with regolith shielding), Lunar orbit, Mars transit (solar min and max), Mars surface (unshielded and in lava tube), Earth-Mars L1. Include data from NASA, ESA RAD experiment on Curiosity, JAXA Kaguya, Chang'e missions. For each provide: Location, Dose_Rate_mSv_per_year, Shielding_Type, Shielded_Dose_mSv_per_year, Career_Limit_mSv (600 per NASA-STD-3001), Years_to_Limit, source URL. Return as CSV. | C5: RAW_Radiation | D5: Location, Dose_Rate_mSv_per_year, Shielding_Type, Shielded_Dose_mSv_per_year, Career_Limit_mSv, Years_to_Limit, SRC_ID, Notes
A6: ISRU Potential | B6: Research In-Situ Resource Utilization capabilities for Moon and Mars. Include: lunar regolith oxygen extraction (MOXIE analog, ilmenite reduction), lunar water ice (LCROSS data, Chandrayaan, VIPER), Mars atmospheric CO2 to O2 (MOXIE results), Mars subsurface water ice (SHARAD/MARSIS data), Mars methane production (Sabatier process). For each provide: Resource, Destination, Extraction_Method, Production_Rate_kg_per_day, Power_Required_kW, TRL, Estimated_Deployment_Year, source URL. Return as CSV. | C6: RAW_ISRU | D6: Resource, Destination, Extraction_Method, Production_Rate_kg_per_day, Power_Required_kW, TRL, Estimated_Deployment_Year, SRC_ID, Notes
A7: Energy Systems | B7: Research power generation systems for space habitats. Include: ISS solar arrays, Kilopower/KRUSTY fission reactor, NASA FSP (Fission Surface Power), Rolls-Royce micro reactor, Mars solar panel efficiency, lunar solar with polar placement, RTGs (MMRTG, Next-Gen RTG), orbital solar power stations. For each provide: System_Name, Provider, Type (Solar/Fission/RTG/Fusion), Power_Output_kW, Mass_Kg, Specific_Power_W_per_kg, Destination_Suitability, TRL, source URL. Return as CSV. | C7: RAW_Energy | D7: System_Name, Provider, Type, Power_Output_kW, Mass_Kg, Specific_Power_W_per_kg, Destination_Suitability, TRL, SRC_ID, Notes
A8: Failure and Recovery Cost | B8: Research costs associated with mission failure and recovery for space missions. Include: historical mission failure costs (Columbia, Challenger adjusted to 2025 USD), ISS emergency scenarios, Artemis abort costs, Mars mission failure scenarios (no recovery possible), LEO commercial station emergency return costs, insurance costs for crewed missions. For each provide: Scenario, Destination, Failure_Type, Estimated_Cost_USD, Recovery_Possible (TRUE/FALSE), Recovery_Time_Days, Human_Risk_Level (Low/Medium/High/Critical), source URL. Return as CSV. | C8: RAW_Failure_Cost | D8: Scenario, Destination, Failure_Type, Estimated_Cost_USD, Recovery_Possible, Recovery_Time_Days, Human_Risk_Level, SRC_ID, Notes
A9: Revenue Models | B9: Research near-term revenue pathways for space destinations. Include: space tourism (LEO, lunar flyby, orbital hotels), satellite servicing, in-space manufacturing (ZBLAN fiber, pharmaceuticals, semiconductors), lunar mining (He-3, rare earths, water), Mars IP/media rights, microgravity research contracts, government anchor tenancy contracts. For each provide: Revenue_Stream, Destination, Estimated_Annual_Revenue_USD, Market_Maturity (Existing/Emerging/Speculative), First_Revenue_Year, Key_Players, source URL. Return as CSV. | C9: RAW_Revenue | D9: Revenue_Stream, Destination, Estimated_Annual_Revenue_USD, Market_Maturity, First_Revenue_Year, Key_Players, SRC_ID, Notes

Sheet SOURCE_REGISTRY
A1: SRC_ID | B1: Short_Name | C1: Full_Citation | D1: URL | E1: Access_Date | F1: Type | G1: Reliability | H1: Agency | I1: Notes
A2: SRC_001 | B2: NASA OIG ISS Cost | C2: NASA Office of Inspector General, ISS Annual Cost Report | D2: https://oig.nasa.gov/ | E2: 2025-01-15 | F2: Report | G2: High | H2: NASA | I2: Annual ISS cost ~$3-4B
A3: SRC_002 | B3: NASA STD 3001 Vol 1 | C3: NASA-STD-3001 Volume 1, Rev C — Crew Health Standard | D3: https://www.nasa.gov/wp-content/uploads/2023/11/nasa-std-3001-vol-1-rev-c-with-signature.pdf | E3: 2025-02-01 | F3: Standard | G3: High | H3: NASA | I3: 600 mSv career limit
A4: SRC_003 | B4: SpaceX Starship | C4: SpaceX Starship payload and cost projections | D4: https://www.spacex.com/vehicles/starship/ | E4: 2025-03-01 | F4: Corporate | G4: Medium | H4: SpaceX | I4: Cost projections are corporate claims
A5: SRC_004 | B5: NASA BVAD | C5: NASA Baseline Values and Assumptions Document, TP-2015-218570/REV2 | D5: https://ntrs.nasa.gov/api/citations/20210024855/downloads/BVAD_2.15.22-final.pdf | E5: 2025-02-15 | F5: Technical Report | G5: High | H5: NASA | I5: ECLSS baseline parameters
A6: SRC_005 | B6: Curiosity RAD | C6: MSL/RAD Mars surface radiation measurements | D6: https://mars.nasa.gov/msl/mission/instruments/rad/ | E6: 2025-01-20 | F6: Instrument Data | G6: High | H6: NASA/JPL | I6: Actual Mars surface measurements
A7: SRC_006 | B7: NASA Gateway ECLSS | C7: Gateway ECLSS Overview, ICES 2022 | D7: https://ntrs.nasa.gov/citations/20220015628 | E7: 2025-02-10 | F7: Conference Paper | G7: High | H7: NASA | I7: 2-4 crew, 30-day expeditions
A8: SRC_007 | B8: MOXIE Results | C8: MOXIE Mars oxygen production results | D8: https://www.nasa.gov/missions/mars-2020-perseverance/perseverance-rover/nasas-moxie-experiment/ | E8: 2025-03-05 | F8: Mission Data | G8: High | H8: NASA/JPL | I8: Actual Mars ISRU demonstration
A9: SRC_008 | B9: Kilopower KRUSTY | C9: Kilopower/KRUSTY fission reactor test results | D9: https://www.nasa.gov/directorates/stmd/tech-demo-missions-program/kilopower/ | E9: 2025-02-20 | F9: Technical Report | G9: High | H9: NASA | I9: 10 kW class, tested 2018
A10: SRC_009 | B10: LCROSS Water | C10: LCROSS lunar water ice detection | D10: https://www.nasa.gov/mission_pages/LCROSS/main/index.html | E10: 2025-01-25 | F10: Mission Data | G10: High | H10: NASA | I10: Confirmed water ice in permanently shadowed craters
A11: SRC_010 | B11: ESA Ariane 6 | C11: ESA Ariane 6 specifications and pricing | D11: https://www.arianespace.com/vehicle/ariane-6/ | E11: 2025-03-10 | F11: Corporate | G11: Medium | H11: ESA | I11: First launch 2024
A12: SRC_011 | B12: URI/Harvard JPG-RR 2024 | C12: Mortreux/Bouxsein dose-response partial gravity study, MHU-8 on ISS, 0/0.33/0.67/1g mice | D12: https://humanresearchroadmap.nasa.gov/Tasks/task.aspx?i=2413 | E12: 2026-04-16 | F12: Peer-reviewed Study | G12: High | H12: NASA/JAXA | I12: 0.67g fully prevents atrophy, 0.33g partially mitigates. Published via URI/Bouxsein/Harvard Medical
... A15: SRC_014 | B15: Bouxsein et al. npj Microgravity 2020 | C15: Dose-dependent skeletal deficits due to varied reductions in mechanical loading in rats | D15: https://www.nature.com/articles/s41526-020-0105-0 | E15: 2026-04-16 | F15: Peer-reviewed Study | G15: High | H15: Harvard | I15: Bone loss proportional to unloading, no plateau at 4 weeks - supports dose-response model

Sheet RAW_Transport_Cost
A1: Provider | B1: Vehicle | C1: Destination | D1: Year | E1: Cost_Per_Kg_USD | F1: Payload_Capacity_Kg | G1: Reusability | H1: Confidence | I1: SRC_ID | J1: Notes
A2: SpaceX | B2: Falcon 9 | C2: LEO | D2: 2024 | E2: 2720 | F2: 22800 | G2: Partial | H2: Actual | I2: SRC_003 | J2: Published pricing ~$67M / 22.8t
A3: SpaceX | B3: Falcon Heavy | C3: LEO | D3: 2024 | E3: 1500 | F3: 63800 | G3: Partial | H3: Actual | I3: SRC_003 | J3: ~$97M expendable pricing
A4: SpaceX | B4: Starship | C4: LEO | D4: 2025 | E4: 100 | F4: 150000 | G4: Full | H4: Projected | I4: SRC_003 | J4: Aspirational target, not demonstrated
A5: SpaceX | B5: Starship | C5: Lunar_Surface | D5: 2026 | E5: 500 | F5: 50000 | G5: Full | H5: Projected | I5: SRC_003 | J5: HLS variant, NASA contract
A6: SpaceX | B6: Starship | C6: Mars_Surface | D6: 2028 | E6: 1000 | F6: 100000 | G6: Full | H6: Estimated | I6: SRC_003 | J6: No firm pricing, Musk statements
A7: NASA | B7: SLS Block 1 | C7: Lunar_Orbit | D7: 2024 | E7: 68000 | F7: 27000 | G7: Expendable | H7: Actual | I7: SRC_001 | J7: ~$2.2B per launch / 27t to TLI (marginal)
A8: NASA | B8: SLS Block 2 | C8: Mars_Orbit | D8: 2030 | E8: 50000 | F8: 46000 | G8: Expendable | H8: Projected | I8: SRC_001 | J8: Block 2 not yet built
A9: ULA | B9: Vulcan Centaur | C9: LEO | D9: 2024 | E9: 9000 | F9: 27200 | G9: Expendable | H9: Contracted | I9: SRC_010 | J9: First launch 2024, ~$250M estimated
A10: ESA | B10: Ariane 6 (A64) | C10: LEO | D10: 2024 | E10: 5400 | F10: 21600 | G10: Expendable | H10: Contracted | I10: SRC_010 | J10: ~$115M target price
A11: JAXA | B11: H3 | C11: LEO | D11: 2024 | E11: 4500 | F11: 6500 | G11: Expendable | H11: Actual | I11: SRC_010 | J11: ~$50M target, reduced from H-IIA
A12: Roscosmos | B12: Proton-M | C12: LEO | D12: 2024 | E12: 4600 | F12: 23000 | G12: Expendable | H12: Actual | I12: SRC_010 | J12: ~$65M, declining availability
A13: Blue Origin | B13: New Glenn | C13: LEO | D13: 2025 | E13: 3500 | F13: 45000 | G13: Partial | H13: Projected | I13: SRC_010 | J13: First stage reusable, no confirmed pricing
... A16: CNSA | B16: Long March 9 | C16: LEO | D16: 2030 | E16: 2000 | F16: 150000 | G16: Partial | H16: Projected | I16: SRC_010 | J16: Super heavy lift, development

Sheet RAW_Operating_Cost
A1: Mission_or_Habitat | B1: Agency_or_Provider | C1: Destination | D1: Year | E1: Annual_Cost_USD | F1: Crew_Size | G1: Cost_Per_Capita_USD | H1: Includes_Transport | I1: Confidence | J1: SRC_ID | K1: Notes
A2: ISS | B2: NASA | C2: LEO | D2: 2024 | E2: 3100000000 | F2: 7 | G2: =E2/F2 -> 4.4285714e+08 | H2: TRUE | I2: Actual | J2: SRC_001 | K2: NASA share ~$3.1B, total ~$4B with partners
A3: ISS | B3: Full Partnership | C3: LEO | D3: 2024 | E3: 4000000000 | F3: 7 | G3: =E3/F3 -> 5.7142857e+08 | H3: TRUE | I3: Actual | J3: SRC_001 | K3: All partner contributions
A4: Tiangong | B4: CNSA | C4: LEO | D4: 2024 | E4: 800000000 | F4: 3 | G4: =E4/F4 -> 2.6666667e+08 | H4: FALSE | I4: Estimated | J4: SRC_010 | K4: Limited public data, analyst estimates
A5: Gateway | B5: NASA | C5: Lunar_Orbit | D5: 2028 | E5: 1500000000 | F5: 4 | G5: =E5/F5 -> 375000000 | H5: FALSE | I5: Projected | J5: SRC_006 | K5: Pre-operational estimates
A6: Artemis Base Camp | B6: NASA | C6: Lunar_Surface | D6: 2030 | E6: 5000000000 | F6: 4 | G6: =E6/F6 -> 1250000000 | H6: TRUE | I6: Estimated | J6: SRC_001 | K6: Includes transport, highly uncertain
A7: Orbital Reef | B7: Blue Origin/Sierra | C7: LEO | D7: 2028 | E7: 500000000 | F7: 10 | G7: =E7/F7 -> 50000000 | H7: FALSE | I7: Projected | J7: SRC_010 | K7: Commercial station, target pricing
A8: Starlab | B8: Voyager/Airbus | C8: LEO | D8: 2029 | E8: 400000000 | F8: 4 | G8: =E8/F8 -> 100000000 | H8: FALSE | I8: Projected | J8: SRC_010 | K8: Based on press reporting
A9: Axiom Station | B9: Axiom Space | C9: LEO | D9: 2027 | E9: 600000000 | F9: 8 | G9: =E9/F9 -> 75000000 | H9: FALSE | I9: Projected | J9: SRC_010 | K9: Modular expansion plan
A10: Mars DRM 5.0 | B10: NASA | C10: Mars_Surface | D10: 2040 | E10: 10000000000 | F10: 6 | G10: =E10/F10 -> 1.6666667e+09 | H10: TRUE | I10: Estimated | J10: SRC_001 | K10: Total mission cost / crew / mission duration
A11: Vast Haven-1 | B11: Vast | C11: LEO | D11: 2027 | E11: 300000000 | F11: 4 | G11: =E11/F11 -> 75000000 | H11: FALSE | I11: Projected | J11: SRC_010 | K11: Early commercial estimates

Sheet RAW_ECLSS
A1: System_Name | B1: Provider | C1: Configuration | D1: Initial_Mass_Kg | E1: Water_Recovery_Pct | F1: O2_Recovery_Pct | G1: Power_Requirement_kW | H1: Crew_Capacity | I1: Mass_Per_Crew_Kg | J1: TRL | K1: SRC_ID | L1: Notes
A2: ISS ECLSS (Current) | B2: NASA/Boeing | C2: Partially_Closed | D2: 9900 | E2: 93 | F2: 42 | G2: 31.5 | H2: 7 | I2: =D2/H2 -> 1414.2857 | J2: 9 | K2: SRC_004 | L2: WRS + OGS + CDRA + TCCS
A3: ISS ECLSS (Upgraded) | B3: NASA | C3: Partially_Closed | D3: 10500 | E3: 98 | F3: 75 | G3: 33 | H3: 7 | I3: =D3/H3 -> 1500 | J3: 7 | K3: SRC_004 | L3: With Brine Processor + improved Sabatier
A4: Gateway ECLSS | B4: NASA/Northrop | C4: Partially_Closed | D4: 2500 | E4: 90 | F4: 0 | G4: 8 | H4: 4 | I4: =D4/H4 -> 625 | J4: 5 | K4: SRC_006 | L4: No O2 recovery, resupply dependent
A5: Exploration ECLSS | B5: NASA | C5: Closed | D5: 15000 | E5: 98 | F5: 75 | G5: 45 | H5: 6 | I5: =D5/H5 -> 2500 | J5: 4 | K5: SRC_004 | L5: Target for Mars transit
A6: MELiSSA | B6: ESA | C6: Closed | D6: 8000 | E6: 95 | F6: 80 | G6: 25 | H6: 4 | I6: =D6/H6 -> 2000 | J6: 3 | K6: SRC_010 | L6: Biological loop, long-term research
A7: Open Loop (Stored) | B7: Generic | C7: Open | D7: 500 | E7: 0 | F7: 0 | G7: 2 | H7: 4 | I7: =D7/H7 -> 125 | J7: 9 | K7: SRC_004 | L7: Baseline: consumables only, ~30 day missions

Sheet RAW_Radiation
A1: Location | B1: Destination | C1: Dose_Rate_mSv_per_year | D1: Shielding_Type | E1: Shielded_Dose_mSv_per_year | F1: Career_Limit_mSv | G1: Years_to_Limit_Unshielded | H1: Years_to_Limit_Shielded | I1: SRC_ID | J1: Notes
A2: ISS Interior | B2: LEO | C2: 150 | D2: Aluminum hull + equipment | E2: 150 | F2: 600 | G2: =F2/C2 -> 4 | H2: =F2/E2 -> 4 | I2: SRC_002 | J2: Shielded by station structure
A3: Lunar Surface (unshielded) | B3: Lunar_Surface | C3: 380 | D3: None | E3: 380 | F3: 600 | G3: =F3/C3 -> 1.5789474 | H3: =F3/E3 -> 1.5789474 | I3: SRC_002 | J3: No magnetic field, no atmosphere
A4: Lunar Surface (regolith 2m) | B4: Lunar_Surface | C4: 380 | D4: 2m regolith | E4: 50 | F4: 600 | G4: =F4/C4 -> 1.5789474 | H4: =F4/E4 -> 12 | I4: SRC_002 | J4: Significant reduction with burial
A5: Lunar Lava Tube | B5: Lunar_Surface | C5: 380 | D5: Natural basalt | E5: 10 | F5: 600 | G5: =F5/C5 -> 1.5789474 | H5: =F5/E5 -> 60 | I5: SRC_002 | J5: Best natural shielding on Moon
A6: Mars Surface (unshielded) | B6: Mars_Surface | C6: 234 | D6: None | E6: 234 | F6: 600 | G6: =F6/C6 -> 2.5641026 | H6: =F6/E6 -> 2.5641026 | I6: SRC_005 | J6: RAD instrument on Curiosity
A7: Mars Surface (regolith 1m) | B7: Mars_Surface | C7: 234 | D7: 1m regolith | E7: 100 | F7: 600 | G7: =F7/C7 -> 2.5641026 | H7: =F7/E7 -> 6 | I7: SRC_005 | J7: Atmosphere provides some shielding
A8: Mars Lava Tube | B8: Mars_Surface | C8: 234 | D8: Natural basalt | E8: 15 | F8: 600 | G8: =F8/C8 -> 2.5641026 | H8: =F8/E8 -> 40 | I8: SRC_005 | J8: Estimated, not measured
A9: Deep Space Transit (solar min) | B9: Mars_Transit | C9: 660 | D9: Aluminum hull | E9: 400 | F9: 600 | G9: =F9/C9 -> 0.90909091 | H9: =F9/E9 -> 1.5 | I9: SRC_002 | J9: GCR dominated during solar minimum
A10: Deep Space Transit (solar max) | B10: Mars_Transit | C10: 400 | D10: Aluminum hull | E10: 250 | F10: 600 | G10: =F10/C10 -> 1.5 | H10: =F10/E10 -> 2.4 | I10: SRC_002 | J10: Lower GCR during solar max but SPE risk
A11: O'Neill Cylinder (shielded) | B11: Orbital | C11: 50 | D11: Regolith/water shield | E11: 20 | F11: 600 | G11: =F11/C11 -> 12 | H11: =F11/E11 -> 30 | I11: SRC_002 | J11: Engineered shielding, no atmosphere needed
A12: ELEO (450km, magnetosphere) | B12: Orbital | C12: 80 | D12: Magnetosphere natural | E12: 80 | F12: 600 | G12: 7.5 | H12: 7.5 | I12: SRC_011 | J12: Globus 2017, ELEO below 500km natural protection
A13: ELEO with water shield (450km) | B13: Orbital | C13: 80 | D13: Water + magnetosphere | E13: 15 | F13: 600 | G13: 7.5 | H13: 40 | I13: SRC_011 | J13: 1m water shield + ELEO

Sheet RAW_Gravity
A1: Location | B1: Gravity_g | C1: Health_Threshold_g | D1: Meets_Threshold | E1: Artificial_Gravity_Feasible | F1: AG_Method | G1: AG_Radius_m | H1: AG_RPM | I1: SRC_ID | J1: Notes
A2: Earth | B2: 1 | C2: 0.67 | D2: TRUE | E2: N/A | F2: N/A | I2: SRC_002 | J2: Baseline
A3: Moon | B3: 0.166 | C3: 0.67 | D3: FALSE | E3: Difficult | F3: Centrifuge | G3: 50 | H3: 4 | I3: SRC_002 | J3: Below 0.67g threshold per JAXA MHU-8 mouse study (URI/Bouxsein 2024); 1/6g prevents muscle atrophy per MHU-2 (Shiba 2019) but bone density loss continues
A4: Mars | B4: 0.378 | C4: 0.67 | D4: FALSE | E4: Difficult | F4: Centrifuge | G4: 50 | H4: 3.8 | I4: SRC_002 | J4: 0.33g test group partially mitigated atrophy, but 0.67g required for full prevention per MHU-8. Cavanagh 2021 meta-analysis: <0.4g insufficient
A5: LEO (ISS) | B5: ~0 | C5: 0.67 | D5: FALSE | E5: YES | F5: Rotating station | G5: 100 | H5: 3 | I5: SRC_002 | J5: Zero-g, countermeasures required
A6: O'Neill Cylinder | B6: 1 | C6: 0.67 | D6: TRUE | E6: Built-in | F6: Rotation | G6: 500 | H6: 1.3 | I6: SRC_002 | J6: Designed for 1g via rotation
A7: Stanford Torus | B7: 1 | C7: 0.67 | D7: TRUE | E7: Built-in | F7: Rotation | G7: 895 | H7: 1.0 | I7: SRC_002 | J7: NASA SP-413 design
A8: Kalpana One | B8: 1 | C8: 0.67 | D8: TRUE | E8: Built-in | F8: Rotation | G8: 250 | H8: 1.9 | I8: SRC_002 | J8: Al Globus design, optimized

Sheet RAW_Comms_Latency
A1: Destination | B1: Min_Latency_Sec | C1: Max_Latency_Sec | D1: Avg_Latency_Sec | E1: Bandwidth_Mbps | F1: Real_Time_Possible | G1: SRC_ID | H1: Notes
A2: LEO | B2: 0.01 | C2: 0.05 | D2: 0.03 | E2: 600 | F2: TRUE | G2: SRC_010 | H2: TDRSS and commercial relay
A3: Lunar_Surface | B3: 1.3 | C3: 1.3 | D3: 1.3 | E3: 100 | F3: Marginal | G3: SRC_010 | H3: ~2.6s round trip
A4: Lunar_Orbit | B4: 1.3 | C4: 1.3 | D4: 1.3 | E4: 100 | F4: Marginal | G4: SRC_010 | H4: Similar to surface
A5: Mars_Surface | B5: 180 | C5: 1320 | D5: 750 | E5: 2 | F5: FALSE | G5: SRC_010 | H5: 3-22 min one-way depending on orbital position
A6: Mars_Orbit | B6: 180 | C6: 1320 | D6: 750 | E6: 2 | F6: FALSE | G6: SRC_010 | H6: Same as surface essentially
A7: Earth-Moon L1 | B7: 1.5 | C7: 1.5 | D7: 1.5 | E7: 100 | F7: Marginal | G7: SRC_010 | H7: Slightly farther than Moon
A8: Earth-Moon L2 | B8: 1.5 | C8: 1.5 | D8: 1.5 | E8: 50 | F8: Marginal | G8: SRC_010 | H8: Behind Moon, relay needed

Sheet RAW_ISRU
A1: Resource | B1: Destination | C1: Extraction_Method | D1: Production_Rate_kg_per_day | E1: Power_Required_kW | F1: TRL | G1: Estimated_Deployment_Year | H1: SRC_ID | I1: Notes
A2: Oxygen | B2: Mars_Surface | C2: CO2 electrolysis (MOXIE) | D2: 0.012 | E2: 0.3 | F2: 6 | G2: 2024 | H2: SRC_007 | I2: MOXIE demonstrated 12g/hr
A3: Oxygen | B3: Mars_Surface | C3: CO2 electrolysis (scaled) | D3: 2 | E3: 25 | F3: 3 | G3: 2035 | H3: SRC_007 | I3: Scaled MOXIE concept
A4: Oxygen | B4: Lunar_Surface | C4: Ilmenite reduction | D4: 10 | E4: 50 | F4: 3 | G4: 2032 | H4: SRC_009 | I4: Requires regolith processing
A5: Oxygen | B5: Lunar_Surface | C5: Molten regolith electrolysis | D5: 5 | E5: 100 | F5: 2 | G5: 2035 | H5: SRC_009 | I5: Higher yield but lower TRL
A6: Water | B6: Lunar_Surface | C6: Ice mining (polar craters) | D6: 50 | E6: 30 | F6: 2 | G6: 2032 | H6: SRC_009 | I6: LCROSS confirmed deposits
A7: Water | B7: Mars_Surface | C7: Subsurface ice extraction | D7: 20 | E7: 15 | F7: 2 | G7: 2035 | H7: SRC_005 | I7: SHARAD data confirms ice sheets
A8: Methane | B8: Mars_Surface | C8: Sabatier process (CO2+H2) | D8: 5 | E8: 10 | F8: 5 | G8: 2030 | H8: SRC_007 | I8: Well-understood chemistry
A9: Metals | B9: Lunar_Surface | C9: Regolith processing | D9: 1 | E9: 200 | F9: 1 | G9: 2040 | H9: SRC_009 | I9: Aluminum, iron, titanium from regolith
A10: He-3 | B10: Lunar_Surface | C10: Regolith heating | D10: 0.001 | E10: 500 | F10: 1 | G10: 2050 | H10: SRC_009 | I10: Extremely low concentration, fusion required

Sheet RAW_Energy
A1: System_Name | B1: Provider | C1: Type | D1: Power_Output_kW | E1: Mass_Kg | F1: Specific_Power_W_per_kg | G1: Destination_Suitability | H1: TRL | I1: SRC_ID | J1: Notes
A2: ISS Solar Arrays | B2: NASA/Boeing | C2: Solar | D2: 120 | E2: 14000 | F2: 8.6 | G2: LEO | H2: 9 | I2: SRC_001 | J2: Current ISS iROSA upgrade to 215 kW
A3: Kilopower (1 kW) | B3: NASA/LANL | C3: Fission | D3: 1 | E3: 226 | F3: 4.4 | G3: Lunar_Surface|Mars_Surface | H3: 5 | I3: SRC_008 | J3: KRUSTY test 2018
A4: Kilopower (10 kW) | B4: NASA/LANL | C4: Fission | D4: 10 | E4: 1500 | F4: 6.7 | G4: Lunar_Surface|Mars_Surface | H4: 4 | I4: SRC_008 | J4: Scaled design
A5: FSP (40 kW) | B5: NASA/DOE | C5: Fission | D5: 40 | E5: 6000 | F5: 6.7 | G5: Lunar_Surface | H5: 4 | I5: SRC_008 | J5: Fission Surface Power, Artemis target
A6: Rolls-Royce Micro Reactor | B6: Rolls-Royce | C6: Fission | D6: 50 | E6: 5000 | F6: 10 | G6: Lunar_Surface|Mars_Surface | H6: 3 | I6: SRC_010 | J6: UK Space Agency funded
A7: Mars Solar Panel | B7: Various | C7: Solar | D7: 10 | E7: 200 | F7: 50 | G7: Mars_Surface | H7: 7 | I7: SRC_005 | J7: 43% of Earth irradiance, dust issue
A8: MMRTG | B8: NASA/DOE | C8: RTG | D8: 0.11 | E8: 45 | F8: 2.4 | G8: Mars_Surface|Deep_Space | H8: 9 | I8: SRC_005 | J8: Curiosity/Perseverance, 14-year life
A9: Next-Gen RTG | B9: NASA/DOE | C9: RTG | D9: 0.5 | E9: 50 | F9: 10 | G9: Mars_Surface|Deep_Space | H9: 4 | I9: SRC_008 | J9: Enhanced efficiency design
A10: Orbital Solar (1 MW) | B10: Various | C10: Solar | D10: 1000 | E10: 10000 | F10: 100 | G10: Orbital | H10: 3 | I10: SRC_010 | J10: Large-scale orbital power station

Sheet RAW_Failure_Cost
A1: Scenario | B1: Destination | C1: Failure_Type | D1: Estimated_Cost_USD | E1: Annual_Probability | F1: Expected_Value_USD | G1: Recovery_Possible | H1: Recovery_Time_Days | I1: Human_Risk_Level | J1: SRC_ID | K1: Notes
A2: ISS Emergency Evacuation | B2: LEO | C2: Crew emergency | D2: 500000000 | E2: 0.05 | F2: =D2*E2 -> 25000000 | G2: TRUE | H2: 1 | I2: Medium | J2: SRC_001 | K2: Soyuz/Dragon always docked
A3: LEO Station Loss | B3: LEO | C3: Structural failure | D3: 5000000000 | E3: 0.001 | F3: =D3*E3 -> 5000000 | G3: FALSE | H3: 0 | I3: Critical | J3: SRC_001 | K3: Total loss scenario
A4: Artemis Abort (transit) | B4: Lunar_Orbit | C4: Mission abort | D4: 2000000000 | E4: 0.03 | F4: =D4*E4 -> 60000000 | G4: TRUE | H4: 5 | I4: High | J4: SRC_001 | K4: Free-return trajectory available
A5: Lunar Surface Emergency | B5: Lunar_Surface | C5: Habitat failure | D5: 3000000000 | E5: 0.1 | F5: =D5*E5 -> 300000000 | G5: TRUE | H5: 7 | I5: Critical | J5: SRC_001 | K5: Requires ascent vehicle + Orion
A6: Mars Transit Failure | B6: Mars_Transit | C6: Vehicle failure | D6: 20000000000 | E6: 0.15 | F6: =D6*E6 -> 3000000000 | G6: FALSE | H6: 0 | I6: Critical | J6: SRC_001 | K6: No rescue possible
A7: Mars Surface Emergency | B7: Mars_Surface | C7: Habitat failure | D7: 25000000000 | E7: 0.15 | F7: =D7*E7 -> 3750000000 | G7: FALSE | H7: 0 | I7: Critical | J7: SRC_001 | K7: No rescue, next window 26 months
A8: Orbital Habitat Emergency | B8: Orbital | C8: Station failure | D8: 2000000000 | E8: 0.05 | F8: =D8*E8 -> 100000000 | G8: TRUE | H8: 1 | I8: Medium | J8: SRC_010 | K8: Commercial station, escape pods
A9: Challenger (adjusted) | B9: LEO | C9: Launch failure | D9: 15000000000 | E9: 0.02 | F9: =D9*E9 -> 300000000 | G9: FALSE | H9: 0 | I9: Critical | J9: SRC_001 | K9: 1986, adjusted to 2025 USD
A10: Columbia (adjusted) | B10: LEO | C10: Reentry failure | D10: 13000000000 | E10: 0.02 | F10: =D10*E10 -> 260000000 | G10: FALSE | H10: 0 | I10: Critical | J10: SRC_001 | K10: 2003, adjusted to 2025 USD

Sheet RAW_Revenue
A1: Revenue_Stream | B1: Destination | C1: Estimated_Annual_Revenue_USD | D1: Market_Maturity | E1: Revenue_Tier | F1: First_Revenue_Year | G1: Key_Players | H1: SRC_ID | I1: Notes
A2: Space Tourism (LEO) | B2: LEO | C2: 3000000000 | D2: Existing | E2: =IF(OR(D2="Existing",D2="Emerging"),"Baseline","Upside") -> Baseline | F2: 2021 | G2: SpaceX, Axiom, SpaceAdventures | H2: SRC_010 | I2: Growing market, Axiom missions
A3: Space Tourism (Lunar Flyby) | B3: Lunar_Orbit | C3: 500000000 | D3: Emerging | E3: =IF(OR(D3="Existing",D3="Emerging"),"Baseline","Upside") -> Baseline | F3: 2026 | G3: SpaceX (dearMoon concept) | H3: SRC_010 | I3: Starship dependent
A4: Microgravity Manufacturing | B4: LEO | C4: 1000000000 | D4: Emerging | E4: =IF(OR(D4="Existing",D4="Emerging"),"Baseline","Upside") -> Baseline | F4: 2025 | G4: Varda Space, Space Forge | H4: SRC_010 | I4: Pharma and fiber optics
A5: Satellite Servicing | B5: LEO | C5: 2000000000 | D5: Existing | E5: =IF(OR(D5="Existing",D5="Emerging"),"Baseline","Upside") -> Baseline | F5: 2020 | G5: Northrop (MEV), Astroscale | H5: SRC_010 | I5: Proven revenue model
A6: Government Anchor Tenancy | B6: LEO | C6: 1500000000 | D6: Existing | E6: =IF(OR(D6="Existing",D6="Emerging"),"Baseline","Upside") -> Baseline | F6: 2024 | G6: NASA CLD program | H6: SRC_010 | I6: $3.9B total committed
A7: Lunar Mining (Water) | B7: Lunar_Surface | C7: 5000000000 | D7: Speculative | E7: =IF(OR(D7="Existing",D7="Emerging"),"Baseline","Upside") -> Upside | F7: 2035 | G7: ispace, Intuitive Machines | H7: SRC_010 | I7: Dependent on demand/infrastructure
A8: He-3 Fusion Fuel | B8: Lunar_Surface | C8: 10000000000 | D8: Speculative | E8: =IF(OR(D8="Existing",D8="Emerging"),"Baseline","Upside") -> Upside | F8: 2050 | G8: None established | H8: SRC_010 | I8: Requires fusion power plants
A9: Mars IP/Media | B9: Mars_Surface | C9: 2000000000 | D9: Speculative | E9: =IF(OR(D9="Existing",D9="Emerging"),"Baseline","Upside") -> Upside | F9: 2035 | G9: SpaceX, National Geographic | H9: SRC_010 | I9: Broadcasting, licensing
A10: In-Space Research | B10: LEO | C10: 800000000 | D10: Existing | E10: =IF(OR(D10="Existing",D10="Emerging"),"Baseline","Upside") -> Baseline | F10: 2020 | G10: Multiple ISS users | H10: SRC_010 | I10: ISS National Lab model

Sheet NORM_ENGINE
A1: Metric_ID | B1: Metric_Name | C1: Source_Sheet | D1: Value_Column | E1: Aggregation | F1: Moon_Raw | G1: Mars_Raw | H1: Orbital_Raw | I1: Lower_Is_Better | J1: Min_Across_All | K1: Max_Across_All | L1: Moon_Normalized | M1: Mars_Normalized | N1: Orbital_Normalized
A2: M01 | B2: Transport Cost ($/kg) | C2: RAW_Transport_Cost | D2: Cost_Per_Kg_USD | E2: Best projected cost by destination (2030+ tech) | F2: {=MIN(IF((RAW_Transport_Cost!C$2:C$100="Lunar_Surface")+(RAW_Transport_Cost!C$2:C$100="Lunar_Orbit"),RAW_Transport_Cost!E$2:E$100))} -> 500 | G2: {=MIN(IF((RAW_Transport_Cost!C$2:C$100="Mars_Surface")+(RAW_Transport_Cost!C$2:C$100="Mars_Orbit"),RAW_Transport_Cost!E$2:E$100))} -> 1000 | H2: {=MIN(IF(RAW_Transport_Cost!C$2:C$100="LEO",RAW_Transport_Cost!E$2:E$100))} -> 100 | I2: TRUE | J2: =MIN(F2,G2,H2) -> 100 | K2: =MAX(F2,G2,H2) -> 1000 | L2: =IF(K2=J2,5,IF(I2="TRUE",1+9*(K2-F2)/(K2-J2),1+9*(F2-J2)/(K2-J2))) -> 6 | M2: =IF(K2=J2,5,IF(I2="TRUE",1+9*(K2-G2)/(K2-J2),1+9*(G2-J2)/(K2-J2))) -> 1 | N2: =IF(K2=J2,5,IF(I2="TRUE",1+9*(K2-H2)/(K2-J2),1+9*(H2-J2)/(K2-J2))) -> 10
A3: M02 | B3: Operating Cost ($/capita/yr) | C3: RAW_Operating_Cost | D3: Cost_Per_Capita_USD | E3: Best projected cost-per-capita by destination | F3: {=MIN(IF((RAW_Operating_Cost!C$2:C$100="Lunar_Surface")+(RAW_Operating_Cost!C$2:C$100="Lunar_Orbit"),RAW_Operating_Cost!G$2:G$100))} -> 375000000 | G3: {=MIN(IF((RAW_Operating_Cost!C$2:C$100="Mars_Surface")+(RAW_Operating_Cost!C$2:C$100="Mars_Orbit"),RAW_Operating_Cost!G$2:G$100))} -> 1.6666667e+09 | H3: {=MIN(IF(RAW_Operating_Cost!C$2:C$100="LEO",RAW_Operating_Cost!G$2:G$100))} -> 50000000 | I3: TRUE | J3: =MIN(F3,G3,H3) -> 50000000 | K3: =MAX(F3,G3,H3) -> 1.6666667e+09 | L3: =IF(K3=J3,5,IF(I3="TRUE",1+9*(K3-F3)/(K3-J3),1+9*(F3-J3)/(K3-J3))) -> 8.1907216 | M3: =IF(K3=J3,5,IF(I3="TRUE",1+9*(K3-G3)/(K3-J3),1+9*(G3-J3)/(K3-J3))) -> 1 | N3: =IF(K3=J3,5,IF(I3="TRUE",1+9*(K3-H3)/(K3-J3),1+9*(H3-J3)/(K3-J3))) -> 10
A4: M03 | B4: ECLSS Water Recovery (%) | C4: RAW_ECLSS | D4: Water_Recovery_Pct | E4: Best available | F4: =MAX(RAW_ECLSS!E$2:E$100) -> 98 | G4: =MAX(RAW_ECLSS!E$2:E$100) -> 98 | H4: =MAX(RAW_ECLSS!E$2:E$100) -> 98 | I4: FALSE | J4: =MIN(F4,G4,H4) -> 98 | K4: =MAX(F4,G4,H4) -> 98 | L4: =IF(K4=J4,5,IF(I4="TRUE",1+9*(K4-F4)/(K4-J4),1+9*(F4-J4)/(K4-J4))) -> 5 | M4: =IF(K4=J4,5,IF(I4="TRUE",1+9*(K4-G4)/(K4-J4),1+9*(G4-J4)/(K4-J4))) -> 5 | N4: =IF(K4=J4,5,IF(I4="TRUE",1+9*(K4-H4)/(K4-J4),1+9*(H4-J4)/(K4-J4))) -> 5
A5: M04 | B5: ECLSS O2 Recovery (%) | C5: RAW_ECLSS | D5: O2_Recovery_Pct | E5: Best available | F5: =MAX(RAW_ECLSS!F$2:F$100) -> 80 | G5: =MAX(RAW_ECLSS!F$2:F$100) -> 80 | H5: =MAX(RAW_ECLSS!F$2:F$100) -> 80 | I5: FALSE | J5: =MIN(F5,G5,H5) -> 80 | K5: =MAX(F5,G5,H5) -> 80 | L5: =IF(K5=J5,5,IF(I5="TRUE",1+9*(K5-F5)/(K5-J5),1+9*(F5-J5)/(K5-J5))) -> 5 | M5: =IF(K5=J5,5,IF(I5="TRUE",1+9*(K5-G5)/(K5-J5),1+9*(G5-J5)/(K5-J5))) -> 5 | N5: =IF(K5=J5,5,IF(I5="TRUE",1+9*(K5-H5)/(K5-J5),1+9*(H5-J5)/(K5-J5))) -> 5
A6: M05 | B6: Radiation Dose (mSv/yr, shielded) | C6: RAW_Radiation | D6: Shielded_Dose_mSv_per_year | E6: Best shielded option by destination | F6: {=MIN(IF(RAW_Radiation!B$2:B$100="Lunar_Surface",RAW_Radiation!E$2:E$100))} -> 10 | G6: {=MIN(IF(RAW_Radiation!B$2:B$100="Mars_Surface",RAW_Radiation!E$2:E$100))} -> 15 | H6: {=MIN(IF(RAW_Radiation!B$2:B$100="Orbital",RAW_Radiation!E$2:E$100))} -> 15 | I6: TRUE | J6: =MIN(F6,G6,H6) -> 10 | K6: =MAX(F6,G6,H6) -> 15 | L6: =IF(F6<50,MAX(5,IF(K6=J6,5,IF(I6="TRUE",1+9*(K6-F6)/(K6-J6),1+9*(F6-J6)/(K6-J6)))),IF(K6=J6,5,IF(I6="TRUE",1+9*(K6-F6)/(K6-J6),1+9*(F6-J6)/(K6-J6)))) -> 10 | M6: =IF(G6<50,MAX(5,IF(K6=J6,5,IF(I6="TRUE",1+9*(K6-G6)/(K6-J6),1+9*(G6-J6)/(K6-J6)))),IF(K6=J6,5,IF(I6="TRUE",1+9*(K6-G6)/(K6-J6),1+9*(G6-J6)/(K6-J6)))) -> 5 | N6: =IF(H6<50,MAX(5,IF(K6=J6,5,IF(I6="TRUE",1+9*(K6-H6)/(K6-J6),1+9*(H6-J6)/(K6-J6)))),IF(K6=J6,5,IF(I6="TRUE",1+9*(K6-H6)/(K6-J6),1+9*(H6-J6)/(K6-J6)))) -> 5
A7: M06 | B7: Gravity (g) | C7: RAW_Gravity | D7: Gravity_g | E7: Native or achievable | F7: =VLOOKUP("Moon",RAW_Gravity!A$2:B$100,2,FALSE()) -> 0.166 | G7: =VLOOKUP("Mars",RAW_Gravity!A$2:B$100,2,FALSE()) -> 0.378 | H7: =VLOOKUP("O'Neill Cylinder",RAW_Gravity!A$2:B$100,2,FALSE()) -> 1 | I7: FALSE | J7: =MIN(F7,G7,H7) -> 0.166 | K7: =MAX(F7,G7,H7) -> 1 | L7: =IF(K7=J7,5,IF(I7="TRUE",1+9*(K7-F7)/(K7-J7),1+9*(F7-J7)/(K7-J7))) -> 1 | M7: =IF(K7=J7,5,IF(I7="TRUE",1+9*(K7-G7)/(K7-J7),1+9*(G7-J7)/(K7-J7))) -> 3.2877698 | N7: =IF(K7=J7,5,IF(I7="TRUE",1+9*(K7-H7)/(K7-J7),1+9*(H7-J7)/(K7-J7))) -> 10
A8: M07 | B8: Comms Latency (sec, avg) | C8: RAW_Comms_Latency | D8: Avg_Latency_Sec | E8: By destination | F8: =VLOOKUP("Lunar_Surface",RAW_Comms_Latency!A$2:D$100,4,FALSE()) -> 1.3 | G8: =VLOOKUP("Mars_Surface",RAW_Comms_Latency!A$2:D$100,4,FALSE()) -> 750 | H8: =VLOOKUP("LEO",RAW_Comms_Latency!A$2:D$100,4,FALSE()) -> 0.03 | I8: TRUE | J8: =MIN(F8,G8,H8) -> 0.03 | K8: =MAX(F8,G8,H8) -> 750 | L8: =IF(K8=J8,5,IF(I8="TRUE",1+9*(K8-F8)/(K8-J8),1+9*(F8-J8)/(K8-J8))) -> 9.9847594 | M8: =IF(K8=J8,5,IF(I8="TRUE",1+9*(K8-G8)/(K8-J8),1+9*(G8-J8)/(K8-J8))) -> 1 | N8: =IF(K8=J8,5,IF(I8="TRUE",1+9*(K8-H8)/(K8-J8),1+9*(H8-J8)/(K8-J8))) -> 10
A9: M08 | B9: ISRU Production (kg/day) | C9: RAW_ISRU | D9: Production_Rate_kg_per_day | E9: Sum projected production kg/day by destination | F9: =SUMPRODUCT((RAW_ISRU!B$2:B$100="Lunar_Surface")*IFERROR(RAW_ISRU!D$2:D$100,0)) -> 66.001 | G9: =SUMPRODUCT((RAW_ISRU!B$2:B$100="Mars_Surface")*IFERROR(RAW_ISRU!D$2:D$100,0)) -> 27.012 | H9: =SUMPRODUCT((RAW_ISRU!B$2:B$100="Orbital")*IFERROR(RAW_ISRU!D$2:D$100,0)) -> 0 | I9: FALSE | J9: =MIN(F9,G9,H9) -> 0 | K9: =MAX(F9,G9,H9) -> 66.001 | L9: =IF(K9=J9,5,IF(I9="TRUE",1+9*(K9-F9)/(K9-J9),1+9*(F9-J9)/(K9-J9))) -> 10 | M9: =IF(K9=J9,5,IF(I9="TRUE",1+9*(K9-G9)/(K9-J9),1+9*(G9-J9)/(K9-J9))) -> 4.6833987 | N9: =IF(K9=J9,5,IF(I9="TRUE",1+9*(K9-H9)/(K9-J9),1+9*(H9-J9)/(K9-J9))) -> 1
A10: M09 | B10: Energy Specific Power (W/kg) | C10: RAW_Energy | D10: Specific_Power_W_per_kg | E10: Best specific power by destination | F10: =SUMPRODUCT(MAX(ISNUMBER(SEARCH("Lunar_Surface",RAW_Energy!G$2:G$100))*RAW_Energy!F$2:F$100)) -> 10 | G10: =SUMPRODUCT(MAX(ISNUMBER(SEARCH("Mars_Surface",RAW_Energy!G$2:G$100))*RAW_Energy!F$2:F$100)) -> 50 | H10: =SUMPRODUCT(MAX((ISNUMBER(SEARCH("Orbital",RAW_Energy!G$2:G$100))+ISNUMBER(SEARCH("LEO",RAW_Energy!G$2:G$100)))*RAW_Energy!F$2:F$100)) -> 100 | I10: FALSE | J10: =MIN(F10,G10,H10) -> 10 | K10: =MAX(F10,G10,H10) -> 100 | L10: =IF(K10=J10,5,IF(I10="TRUE",1+9*(K10-F10)/(K10-J10),1+9*(F10-J10)/(K10-J10))) -> 1 | M10: =IF(K10=J10,5,IF(I10="TRUE",1+9*(K10-G10)/(K10-J10),1+9*(G10-J10)/(K10-J10))) -> 5 | N10: =IF(K10=J10,5,IF(I10="TRUE",1+9*(K10-H10)/(K10-J10),1+9*(H10-J10)/(K10-J10))) -> 10
A11: M10 | B11: Failure Expected Value ($) | C11: RAW_Failure_Cost | D11: Expected_Value_USD | E11: Max expected value (cost x probability) by destination | F11: {=MAX(IF((RAW_Failure_Cost!B$2:B$100="Lunar_Surface")+(RAW_Failure_Cost!B$2:B$100="Lunar_Orbit"),RAW_Failure_Cost!F$2:F$100))} -> 300000000 | G11: {=MAX(IF((RAW_Failure_Cost!B$2:B$100="Mars_Surface")+(RAW_Failure_Cost!B$2:B$100="Mars_Transit"),RAW_Failure_Cost!F$2:F$100))} -> 3750000000 | H11: {=MAX(IF((RAW_Failure_Cost!B$2:B$100="LEO")+(RAW_Failure_Cost!B$2:B$100="Orbital"),RAW_Failure_Cost!F$2:F$100))} -> 300000000 | I11: TRUE | J11: =MIN(F11,G11,H11) -> 300000000 | K11: =MAX(F11,G11,H11) -> 3750000000 | L11: =IF(K11=J11,5,IF(I11="TRUE",1+9*(K11-F11)/(K11-J11),1+9*(F11-J11)/(K11-J11))) -> 10 | M11: =IF(K11=J11,5,IF(I11="TRUE",1+9*(K11-G11)/(K11-J11),1+9*(G11-J11)/(K11-J11))) -> 1 | N11: =IF(K11=J11,5,IF(I11="TRUE",1+9*(K11-H11)/(K11-J11),1+9*(H11-J11)/(K11-J11))) -> 10
A12: M11 | B12: Revenue Potential Baseline ($/yr) | C12: RAW_Revenue | D12: Estimated_Annual_Revenue_USD | E12: Sum baseline tier (Existing + Emerging) | F12: =SUMPRODUCT((RAW_Revenue!B$2:B$100="Lunar_Surface")*(RAW_Revenue!E$2:E$100="Baseline")*IFERROR(RAW_Revenue!C$2:C$100,0)) -> 0 | G12: =SUMPRODUCT((RAW_Revenue!B$2:B$100="Mars_Surface")*(RAW_Revenue!E$2:E$100="Baseline")*IFERROR(RAW_Revenue!C$2:C$100,0)) -> 0 | H12: =SUMPRODUCT(((RAW_Revenue!B$2:B$100="LEO")+(RAW_Revenue!B$2:B$100="Orbital"))*(RAW_Revenue!E$2:E$100="Baseline")*IFERROR(RAW_Revenue!C$2:C$100,0)) -> 8300000000 | I12: FALSE | J12: =MIN(F12,G12,H12) -> 0 | K12: =MAX(F12,G12,H12) -> 8300000000 | L12: =IF(K12=J12,5,IF(I12="TRUE",1+9*(K12-F12)/(K12-J12),1+9*(F12-J12)/(K12-J12))) -> 1 | M12: =IF(K12=J12,5,IF(I12="TRUE",1+9*(K12-G12)/(K12-J12),1+9*(G12-J12)/(K12-J12))) -> 1 | N12: =IF(K12=J12,5,IF(I12="TRUE",1+9*(K12-H12)/(K12-J12),1+9*(H12-J12)/(K12-J12))) -> 10
A13: M12 | B13: Revenue Upside (Speculative - sensitivity only) | C13: RAW_Revenue | D13: Estimated_Annual_Revenue_USD | E13: Sum speculative tier (documentation only) | F13: =SUMPRODUCT((RAW_Revenue!B$2:B$100="Lunar_Surface")*(RAW_Revenue!E$2:E$100="Upside")*IFERROR(RAW_Revenue!C$2:C$100,0)) -> 15000000000 | G13: =SUMPRODUCT((RAW_Revenue!B$2:B$100="Mars_Surface")*(RAW_Revenue!E$2:E$100="Upside")*IFERROR(RAW_Revenue!C$2:C$100,0)) -> 2000000000 | H13: =SUMPRODUCT(((RAW_Revenue!B$2:B$100="LEO")+(RAW_Revenue!B$2:B$100="Orbital"))*(RAW_Revenue!E$2:E$100="Upside")*IFERROR(RAW_Revenue!C$2:C$100,0)) -> 0 | I13: FALSE
A14: INSTRUCTIONS:
A15: INSTRUCTIONS:
A16: 1. Add rows to RAW_* sheets - formulas auto-extend to row 100
A17: 2. Aggregation = best projected value per destination (forward-looking 2030+)
A18: 3. Normalization: IF(Lower_Is_Better, 1+9*(Max-Raw)/(Max-Min), 1+9*(Raw-Min)/(Max-Min))
A19: 4. Result: 1-10 scale where 10 = best for colonization
A20: 5. M10 Failure now uses Expected Value (Cost x Probability)
A21: 6. M11 Revenue scored on Baseline only (Existing+Emerging); M12 is sensitivity
A22: 7. M12 is not used in scoring - documents speculative upside
A23: 8. M05 Radiation: absolute safety floor at 50 mSv/yr (values under threshold score minimum 5)

Sheet SCORING_MATRIX
A1: Requirement | B1: NASA_Hazard_or_WA_Pillar | C1: Tier | D1: Metric_Type | E1: Weight | F1: Moon_Score | G1: Mars_Score | H1: Orbital_Score | I1: Moon_Weighted | J1: Mars_Weighted | K1: Orbital_Weighted | L1: Data_Source | M1: Justification
A2: Gravity >0.67g | B2: Gravity Fields | C2: 1 | D2: QUANTITATIVE | E2: 10 | F2: =IFERROR(NORM_ENGINE!L7,"") -> 1 | G2: =IFERROR(NORM_ENGINE!M7,"") -> 3.2877698 | H2: =IFERROR(NORM_ENGINE!N7,"") -> 10 | I2: =IFERROR(E2*F2,0) -> 10 | J2: =IFERROR(E2*G2,0) -> 32.877698 | K2: =IFERROR(E2*H2,0) -> 100 | L2: RAW_Gravity → NORM_ENGINE M06 | M2: Native gravity vs 0.67g threshold (URI/Harvard 2026 mouse study)
A3: Radiation <600 mSv/career | B3: Radiation | C3: 1 | D3: QUANTITATIVE | E3: 9 | F3: =IFERROR(NORM_ENGINE!L6,"") -> 10 | G3: =IFERROR(NORM_ENGINE!M6,"") -> 5 | H3: =IFERROR(NORM_ENGINE!N6,"") -> 5 | I3: =IFERROR(E3*F3,0) -> 90 | J3: =IFERROR(E3*G3,0) -> 45 | K3: =IFERROR(E3*H3,0) -> 45 | L3: RAW_Radiation → NORM_ENGINE M05 | M3: Shielded dose rate, years to career limit
A4: Closed-loop ECLSS | B4: Hostile/Closed Env | C4: 1 | D4: QUANTITATIVE | E4: 9 | F4: =IFERROR(NORM_ENGINE!L4,"") -> 5 | G4: =IFERROR(NORM_ENGINE!M4,"") -> 5 | H4: =IFERROR(NORM_ENGINE!N4,"") -> 5 | I4: =IFERROR(E4*F4,0) -> 45 | J4: =IFERROR(E4*G4,0) -> 45 | K4: =IFERROR(E4*H4,0) -> 45 | L4: RAW_ECLSS → NORM_ENGINE M03 | M4: Water recovery % as proxy
A5: Breathable atmosphere generation | B5: Hostile/Closed Env | C5: 1 | D5: QUANTITATIVE | E5: 9 | F5: =IFERROR(NORM_ENGINE!L5,"") -> 5 | G5: =IFERROR(NORM_ENGINE!M5,"") -> 5 | H5: =IFERROR(NORM_ENGINE!N5,"") -> 5 | I5: =IFERROR(E5*F5,0) -> 45 | J5: =IFERROR(E5*G5,0) -> 45 | K5: =IFERROR(E5*H5,0) -> 45 | L5: RAW_ECLSS → NORM_ENGINE M04 | M5: O2 recovery %
A6: Emergency return path (RTO) | B6: Distance from Earth | C6: 2 | D6: QUANTITATIVE | E6: 8 | F6: =IFERROR((NORM_ENGINE!L8+NORM_ENGINE!L11)/2,"") -> 9.9923797 | G6: =IFERROR((NORM_ENGINE!M8+NORM_ENGINE!M11)/2,"") -> 1 | H6: =IFERROR((NORM_ENGINE!N8+NORM_ENGINE!N11)/2,"") -> 10 | I6: =IFERROR(E6*F6,0) -> 79.939038 | J6: =IFERROR(E6*G6,0) -> 8 | K6: =IFERROR(E6*H6,0) -> 80 | L6: RAW_Comms_Latency + RAW_Failure_Cost | M6: Composite: latency + recovery feasibility
A7: Supply chain resilience (RPO) | B7: Distance from Earth | C7: 2 | D7: QUANTITATIVE | E7: 8 | F7: =IFERROR((NORM_ENGINE!L2+NORM_ENGINE!L9)/2,"") -> 8 | G7: =IFERROR((NORM_ENGINE!M2+NORM_ENGINE!M9)/2,"") -> 2.8416994 | H7: =IFERROR((NORM_ENGINE!N2+NORM_ENGINE!N9)/2,"") -> 5.5 | I7: =IFERROR(E7*F7,0) -> 64 | J7: =IFERROR(E7*G7,0) -> 22.733595 | K7: =IFERROR(E7*H7,0) -> 44 | L7: RAW_Transport_Cost + RAW_ISRU | M7: Transport cost + ISRU self-sufficiency
A8: Communications latency | B8: Distance from Earth | C8: 2 | D8: QUANTITATIVE | E8: 5 | F8: =IFERROR(NORM_ENGINE!L8,"") -> 9.9847594 | G8: =IFERROR(NORM_ENGINE!M8,"") -> 1 | H8: =IFERROR(NORM_ENGINE!N8,"") -> 10 | I8: =IFERROR(E8*F8,0) -> 49.923797 | J8: =IFERROR(E8*G8,0) -> 5 | K8: =IFERROR(E8*H8,0) -> 50 | L8: RAW_Comms_Latency → NORM_ENGINE M07 | M8: Signal delay seconds
A9: Behavioral health / crew sustainability | B9: Isolation/Confinement | C9: 2 | D9: QUALITATIVE | E9: 6 | F9: =IFERROR(QUAL_JUSTIFICATIONS!B2,"") -> 7 | G9: =IFERROR(QUAL_JUSTIFICATIONS!E2,"") -> 3 | H9: =IFERROR(QUAL_JUSTIFICATIONS!H2,"") -> 6 | I9: =IFERROR(E9*F9,0) -> 42 | J9: =IFERROR(E9*G9,0) -> 18 | K9: =IFERROR(E9*H9,0) -> 36 | L9: QUAL_JUSTIFICATIONS | M9: Expert rated, see justification sheet
A10: ISRU potential | B10: Performance | C10: 3 | D10: QUANTITATIVE | E10: 7 | F10: =IFERROR(NORM_ENGINE!L9,"") -> 10 | G10: =IFERROR(NORM_ENGINE!M9,"") -> 4.6833987 | H10: =IFERROR(NORM_ENGINE!N9,"") -> 1 | I10: =IFERROR(E10*F10,0) -> 70 | J10: =IFERROR(E10*G10,0) -> 32.783791 | K10: =IFERROR(E10*H10,0) -> 7 | L10: RAW_ISRU → NORM_ENGINE M08 | M10: Total production rate kg/day
A11: Energy independence | B11: Performance | C11: 3 | D11: QUANTITATIVE | E11: 7 | F11: =IFERROR(NORM_ENGINE!L10,"") -> 1 | G11: =IFERROR(NORM_ENGINE!M10,"") -> 5 | H11: =IFERROR(NORM_ENGINE!N10,"") -> 10 | I11: =IFERROR(E11*F11,0) -> 7 | J11: =IFERROR(E11*G11,0) -> 35 | K11: =IFERROR(E11*H11,0) -> 70 | L11: RAW_Energy → NORM_ENGINE M09 | M11: Specific power W/kg
